Workbook

Sheet Cover
A1: SALVATORE PIZZA — COVER
A3: Salvatore Pizza | Financial Model & Investment Case
A4: Sofia, Bulgaria | 5-Year Projection | Currency: BGN (EUR @ 1.95583)
A6: Concept: | B6: Authentic Neapolitan pizzeria — 48h fermented dough, signature stuffed-mozzarella crust
A7: Location: | B7: 19 Gurko Str., Central Sofia, Bulgaria
A8: Capacity: | B8: 1 wood-fired oven, 6 in-shop tables, delivery via aggregator
A9: Hours: | B9: 11:00 – 23:00, 7 days/week (~360 trading days/yr)
A10: Prepared by: | B10: Goldman Sachs — Restaurant & Hospitality Coverage
A11: Date: | B11: 2026-05-20
A14: CENTRAL CASE — HEADLINE KPIs
A16: Year-1 Revenue (BGN) | C16: ='P&L'!C5
A17: Year-5 Revenue (BGN) | C17: ='P&L'!G5
A18: Y3 EBITDA Margin | C18: ='P&L'!E22
A19: Y5 EBITDA Margin | C19: ='P&L'!G22
A20: Project IRR | C20: ='Cash Flow'!C25
A21: Payback Period (yrs) | C21: ='Cash Flow'!C27
A22: NPV @ 12% (BGN) | C22: ='Cash Flow'!C24
A23: MOIC | C23: ='Cash Flow'!C26
A26: Investment Thesis (Central Case)
A27: • Premium positioning via stuffed-mozzarella signature crust differentiates from Sofia's commodity Neapolitan field.
A28: • Single-oven, 6-table footprint with delivery upside keeps fixed-cost base lean; break-even achievable in Y1.
A29: • Bulgaria's 10% CIT, 9% reduced-VAT on food, and sub-EU labour costs underpin attractive unit economics.
A30: • Key risks: aggregator commission compression of delivery margin; oven throughput ceiling at 180 pizzas/day.
A34: Prepared by Goldman Sachs Restaurant & Hospitality Coverage | Confidential Due Diligence Draft | 2026-05-20

Sheet Assumptions
A1: SALVATORE PIZZA — ASSUMPTIONS
A3: All Bulgaria/Sofia benchmarks anchored to 2025-26 market data. Inputs in BLUE are flex-able drivers.
A5: Operating Parameters
A6: Driver | B6: Value | C6: Unit | E6: Source / Note
A7: Trading days per year | B7: 360 | C7: days | E7: Open 7 days/week, allow 5 closed days
A8: Trading hours per day | B8: 12 | C8: hrs | E8: 11:00–23:00
A9: Unit size | B9: 90 | C9: m² | E9: Central Sofia 90 m² assumption
A10: EUR / BGN fixed peg | B10: 1.95583 | C10: BGN/EUR | E10: Bulgaria currency board peg
A11: Scenario (Base/Bull/Bear) | B11: Base | C11: — | E11: Drives flex on covers/day & ASP via ±15% in calcs
A12: Scenario flex — Bull (+) / Bear (-) | B12: 0.15 | C12: % | E12: Applied to covers and ASP under Bull/Bear
A14: Revenue Drivers
A15: Driver | B15: Value | C15: Unit | E15: Source / Note
A16: # tables in-shop | B16: 6 | C16: tables | E16: Physical constraint
A17: Covers per table (seats) | B17: 4 | C17: pax | E17: Standard 4-top
A18: Lunch turns/day Y1 | B18: 1 | C18: turns | E18: Ramping to 1.4 by Y3
A19: Dinner turns/day Y1 | B19: 1.5 | C19: turns | E19: Ramping to 2.3 by Y3 (Sofia central peak)
A20: Lunch turns/day Y3 (steady) | B20: 1.4 | C20: turns | E20: Steady state
A21: Dinner turns/day Y3 (steady) | B21: 2.3 | C21: turns | E21: Steady state
A22: Avg dine-in ticket (BGN/cover) | B22: 34 | C22: BGN | E22: Pizza ASP 24 + drink + occasional side
A23: Takeaway orders/day Y1 | B23: 12 | C23: orders | E23: Walk-in pickup
A24: Takeaway orders/day Y3 (steady) | B24: 25 | C24: orders | E24: Steady
A25: Avg takeaway ticket (BGN) | B25: 26 | C25: BGN | E25: Pizza + small drink
A26: Delivery orders/day Y1 | B26: 18 | C26: orders | E26: Via Glovo/Foodpanda Sofia
A27: Delivery orders/day Y3 (steady) | B27: 45 | C27: orders | E27: Aggressive ramp to 45 by Y3
... A33: Oven max throughput (pizza/day) | B33: 180 | C33: pizzas | E33: Single Neapolitan oven peak — flag if breached
A35: Cost Drivers
A36: Driver | B36: Value | C36: Unit | E36: Source / Note
A37: Food COGS % of food revenue | B37: 0.3 | C37: % | E37: Neapolitan target 28–32%; stuffed crust +2% cheese
A38: Beverage COGS % of bev revenue | B38: 0.25 | C38: % | E38: Bulgaria casual-dining benchmark
A39: Beverage share of revenue | B39: 0.18 | C39: % | E39: Blended bev share
A40: Aggregator commission % | B40: 0.3 | C40: % | E40: Glovo/Foodpanda Bulgaria 28–32%; own fleet would lower
A41: Rent BGN/month | B41: 6500 | C41: BGN/mo | E41: Central Sofia 90 m² @ ~72 BGN/m²/mo
A42: Rent annual indexation | B42: 0.03 | C42: % | E42: Lease escalator
A43: Utilities base BGN/month | B43: 1500 | C43: BGN/mo | E43: Power/water/internet
A44: Oven gas/wood BGN/month | B44: 750 | C44: BGN/mo | E44: Wood-fired oven fuel
A45: Head chef gross BGN/month | B45: 3500 | C45: BGN/mo | E45: Senior Italian-trained
A46: Pizzaioli x2 gross BGN/month each | B46: 2200 | C46: BGN/mo | E46: Bulgaria restaurant skilled wage
A47: Waiters x2 gross BGN/month each | B47: 1500 | C47: BGN/mo | E47: Above Bulgaria min wage 1,077
A48: Delivery coordinator (PT) BGN/month | B48: 1200 | C48: BGN/mo | E48: Part-time logistics
... A57: Misc % of revenue | B57: 0.01 | C57: % | E57: Buffer for one-offs
...

Sheet Revenue Build
A1: SALVATORE PIZZA — REVENUE BUILD
A3: Annual roll-up. Scenario flex applies multiplier to covers/day and ASP.
A4: Line | B4: Driver / Unit | C4: Y1 2026 | D4: Y2 2027 | E4: Y3 2028 | F4: Y4 2029 | G4: Y5 2030
A6: Scenario multiplier (volume & ASP) | B6: x | C6: =IF(Assumptions!$B$11="Bull",1+Assumptions!$B$12,IF(Assumptions!$B$11="Bear",1-Assumptions!$B$12,1)) | D6: =IF(Assumptions!$B$11="Bull",1+Assumptions!$B$12,IF(Assumptions!$B$11="Bear",1-Assumptions!$B$12,1)) | E6: =IF(Assumptions!$B$11="Bull",1+Assumptions!$B$12,IF(Assumptions!$B$11="Bear",1-Assumptions!$B$12,1)) | F6: =IF(Assumptions!$B$11="Bull",1+Assumptions!$B$12,IF(Assumptions!$B$11="Bear",1-Assumptions!$B$12,1)) | G6: =IF(Assumptions!$B$11="Bull",1+Assumptions!$B$12,IF(Assumptions!$B$11="Bear",1-Assumptions!$B$12,1))
A8: DINE-IN
A9: Tables × seats/table | B9: pax | C9: =Assumptions!$B$16*Assumptions!$B$17 | D9: =Assumptions!$B$16*Assumptions!$B$17 | E9: =Assumptions!$B$16*Assumptions!$B$17 | F9: =Assumptions!$B$16*Assumptions!$B$17 | G9: =Assumptions!$B$16*Assumptions!$B$17
A10: Lunch turns/day | B10: turns | C10: =Assumptions!$B$18 | D10: =(Assumptions!$B$18+Assumptions!$B$20)/2 | E10: =Assumptions!$B$20 | F10: =Assumptions!$B$20 | G10: =Assumptions!$B$20
A11: Dinner turns/day | B11: turns | C11: =Assumptions!$B$19 | D11: =(Assumptions!$B$19+Assumptions!$B$21)/2 | E11: =Assumptions!$B$21 | F11: =Assumptions!$B$21 | G11: =Assumptions!$B$21
A12: Daily covers (lunch + dinner) | B12: covers | C12: =C9*(C10+C11)*C6 | D12: =D9*(D10+D11)*D6 | E12: =E9*(E10+E11)*E6 | F12: =F9*(F10+F11)*F6 | G12: =G9*(G10+G11)*G6
A13: Avg ticket BGN/cover (scen-flexed) | B13: BGN | C13: =Assumptions!$B$22*C6 | D13: =Assumptions!$B$22*D6 | E13: =Assumptions!$B$22*E6 | F13: =Assumptions!$B$22*F6 | G13: =Assumptions!$B$22*G6
A14: Dine-in revenue (annual) | B14: BGN | C14: =C12*C13*Assumptions!$B$7 | D14: =C14*(1+Assumptions!$B$29) | E14: =D14*(1+Assumptions!$B$30) | F14: =E14*(1+Assumptions!$B$31) | G14: =F14*(1+Assumptions!$B$32)
A16: TAKEAWAY
A17: Takeaway orders/day | B17: orders | C17: =Assumptions!$B$23*C6 | D17: =(Assumptions!$B$23+Assumptions!$B$24)/2*D6 | E17: =Assumptions!$B$24*E6 | F17: =Assumptions!$B$24*F6 | G17: =Assumptions!$B$24*G6
A18: Avg ticket (scen-flexed) | B18: BGN | C18: =Assumptions!$B$25*C6 | D18: =Assumptions!$B$25*D6 | E18: =Assumptions!$B$25*E6 | F18: =Assumptions!$B$25*F6 | G18: =Assumptions!$B$25*G6
A19: Takeaway revenue (annual) | B19: BGN | C19: =C17*C18*Assumptions!$B$7 | D19: =C19*(1+Assumptions!$B$29) | E19: =D19*(1+Assumptions!$B$30) | F19: =E19*(1+Assumptions!$B$31) | G19: =F19*(1+Assumptions!$B$32)
A21: DELIVERY (gross)
A22: Delivery orders/day | B22: orders | C22: =Assumptions!$B$26*C6 | D22: =(Assumptions!$B$26+Assumptions!$B$27)/2*D6 | E22: =Assumptions!$B$27*E6 | F22: =Assumptions!$B$27*F6 | G22: =Assumptions!$B$27*G6
A23: Avg ticket gross (scen-flexed) | B23: BGN | C23: =Assumptions!$B$28*C6 | D23: =Assumptions!$B$28*D6 | E23: =Assumptions!$B$28*E6 | F23: =Assumptions!$B$28*F6 | G23: =Assumptions!$B$28*G6
A24: Delivery revenue GROSS (annual) | B24: BGN | C24: =C22*C23*Assumptions!$B$7 | D24: =C24*(1+Assumptions!$B$29) | E24: =D24*(1+Assumptions!$B$30) | F24: =E24*(1+Assumptions!$B$31) | G24: =F24*(1+Assumptions!$B$32)
A25: Less: aggregator commission | B25: BGN | C25: =-C24*Assumptions!$B$40 | D25: =-D24*Assumptions!$B$40 | E25: =-E24*Assumptions!$B$40 | F25: =-F24*Assumptions!$B$40 | G25: =-G24*Assumptions!$B$40
A26: Delivery revenue NET (annual) | B26: BGN | C26: =C24+C25 | D26: =D24+D25 | E26: =E24+E25 | F26: =F24+F25 | G26: =G24+G25
A28: TOTAL REVENUE (Net) | B28: BGN | C28: =C14+C19+C26 | D28: =D14+D19+D26 | E28: =E14+E19+E26 | F28: =F14+F19+F26 | G28: =G14+G19+G26
A29: of which: Gross delivery (for COGS/comm calc) | C29: =C24 | D29: =D24 | E29: =E24 | F29: =F24 | G29: =G24
A31: OVEN CAPACITY CHECK
A32: Implied pizzas/day (≈ 90% of orders) | B32: pizzas | C32: =(C12*0.7+C17+C22) | D32: =(D12*0.7+D17+D22) | E32: =(E12*0.7+E17+E22) | F32: =(F12*0.7+F17+F22) | G32: =(G12*0.7+G17+G22)
A33: Oven ceiling (pizzas/day) | B33: pizzas | C33: =Assumptions!$B$33 | D33: =Assumptions!$B$33 | E33: =Assumptions!$B$33 | F33: =Assumptions!$B$33 | G33: =Assumptions!$B$33
A34: Utilisation | C34: =C32/C33 | D34: =D32/D33 | E34: =E32/E33 | F34: =F32/F33 | G34: =G32/G33

Sheet Cost Forecast
A1: SALVATORE PIZZA — COST FORECAST
A3: Each cost shown in BGN and as % of total revenue. Linked to Revenue Build & Assumptions.
A4: Cost Line | B4: Y1 2026 | D4: Y2 2027 | F4: Y3 2028 | H4: Y4 2029 | J4: Y5 2030
B5: BGN | C5: % rev | D5: BGN | E5: % rev | F5: BGN | G5: % rev | H5: BGN | I5: % rev | J5: BGN | K5: % rev
A6: Total Revenue (ref) | B6: ='Revenue Build'!C28 | D6: ='Revenue Build'!D28 | F6: ='Revenue Build'!E28 | H6: ='Revenue Build'!F28 | J6: ='Revenue Build'!G28
A7: COGS
A8: Food COGS | B8: ='Revenue Build'!C28*(1-Assumptions!$B$39)*Assumptions!$B$37 | C8: =IFERROR(B8/B6,0) | D8: ='Revenue Build'!D28*(1-Assumptions!$B$39)*Assumptions!$B$37 | E8: =IFERROR(D8/D6,0) | F8: ='Revenue Build'!E28*(1-Assumptions!$B$39)*Assumptions!$B$37 | G8: =IFERROR(F8/F6,0) | H8: ='Revenue Build'!F28*(1-Assumptions!$B$39)*Assumptions!$B$37 | I8: =IFERROR(H8/H6,0) | J8: ='Revenue Build'!G28*(1-Assumptions!$B$39)*Assumptions!$B$37 | K8: =IFERROR(J8/J6,0)
A9: Beverage COGS | B9: ='Revenue Build'!C28*Assumptions!$B$39*Assumptions!$B$38 | C9: =IFERROR(B9/B6,0) | D9: ='Revenue Build'!D28*Assumptions!$B$39*Assumptions!$B$38 | E9: =IFERROR(D9/D6,0) | F9: ='Revenue Build'!E28*Assumptions!$B$39*Assumptions!$B$38 | G9: =IFERROR(F9/F6,0) | H9: ='Revenue Build'!F28*Assumptions!$B$39*Assumptions!$B$38 | I9: =IFERROR(H9/H6,0) | J9: ='Revenue Build'!G28*Assumptions!$B$39*Assumptions!$B$38 | K9: =IFERROR(J9/J6,0)
A10: Aggregator commission (memo — netted in rev) | B10: ='Revenue Build'!C24*Assumptions!$B$40 | C10: =IFERROR(B10/B6,0) | D10: ='Revenue Build'!D24*Assumptions!$B$40 | E10: =IFERROR(D10/D6,0) | F10: ='Revenue Build'!E24*Assumptions!$B$40 | G10: =IFERROR(F10/F6,0) | H10: ='Revenue Build'!F24*Assumptions!$B$40 | I10: =IFERROR(H10/H6,0) | J10: ='Revenue Build'!G24*Assumptions!$B$40 | K10: =IFERROR(J10/J6,0)
A11: Total COGS | B11: =B8+B9 | C11: =IFERROR(B11/B6,0) | D11: =D8+D9 | E11: =IFERROR(D11/D6,0) | F11: =F8+F9 | G11: =IFERROR(F11/F6,0) | H11: =H8+H9 | I11: =IFERROR(H11/H6,0) | J11: =J8+J9 | K11: =IFERROR(J11/J6,0)
A13: OPERATING EXPENSES
A14: Rent | B14: =Assumptions!$B$41*12*(1+Assumptions!$B$42)^0 | C14: =IFERROR(B14/B6,0) | D14: =Assumptions!$B$41*12*(1+Assumptions!$B$42)^1 | E14: =IFERROR(D14/D6,0) | F14: =Assumptions!$B$41*12*(1+Assumptions!$B$42)^2 | G14: =IFERROR(F14/F6,0) | H14: =Assumptions!$B$41*12*(1+Assumptions!$B$42)^3 | I14: =IFERROR(H14/H6,0) | J14: =Assumptions!$B$41*12*(1+Assumptions!$B$42)^4 | K14: =IFERROR(J14/J6,0)
A15: Utilities & oven fuel | B15: =(Assumptions!$B$43+Assumptions!$B$44)*12 | C15: =IFERROR(B15/B6,0) | D15: =(Assumptions!$B$43+Assumptions!$B$44)*12 | E15: =IFERROR(D15/D6,0) | F15: =(Assumptions!$B$43+Assumptions!$B$44)*12 | G15: =IFERROR(F15/F6,0) | H15: =(Assumptions!$B$43+Assumptions!$B$44)*12 | I15: =IFERROR(H15/H6,0) | J15: =(Assumptions!$B$43+Assumptions!$B$44)*12 | K15: =IFERROR(J15/J6,0)
A16: Labour (incl. 19% social) | B16: =(Assumptions!$B$45+2*Assumptions!$B$46+2*Assumptions!$B$47+Assumptions!$B$48)*12*(1+Assumptions!$B$49) | C16: =IFERROR(B16/B6,0) | D16: =(Assumptions!$B$45+2*Assumptions!$B$46+2*Assumptions!$B$47+Assumptions!$B$48)*12*(1+Assumptions!$B$49) | E16: =IFERROR(D16/D6,0) | F16: =(Assumptions!$B$45+2*Assumptions!$B$46+2*Assumptions!$B$47+Assumptions!$B$48)*12*(1+Assumptions!$B$49) | G16: =IFERROR(F16/F6,0) | H16: =(Assumptions!$B$45+2*Assumptions!$B$46+2*Assumptions!$B$47+Assumptions!$B$48)*12*(1+Assumptions!$B$49) | I16: =IFERROR(H16/H6,0) | J16: =(Assumptions!$B$45+2*Assumptions!$B$46+2*Assumptions!$B$47+Assumptions!$B$48)*12*(1+Assumptions!$B$49) | K16: =IFERROR(J16/J6,0)
A17: Marketing | B17: ='Revenue Build'!C28*Assumptions!$B$50 | C17: =IFERROR(B17/B6,0) | D17: ='Revenue Build'!D28*Assumptions!$B$51 | E17: =IFERROR(D17/D6,0) | F17: ='Revenue Build'!E28*Assumptions!$B$51 | G17: =IFERROR(F17/F6,0) | H17: ='Revenue Build'!F28*Assumptions!$B$51 | I17: =IFERROR(H17/H6,0) | J17: ='Revenue Build'!G28*Assumptions!$B$51 | K17: =IFERROR(J17/J6,0)
A18: Repairs & maintenance | B18: ='Revenue Build'!C28*Assumptions!$B$52 | C18: =IFERROR(B18/B6,0) | D18: ='Revenue Build'!D28*Assumptions!$B$52 | E18: =IFERROR(D18/D6,0) | F18: ='Revenue Build'!E28*Assumptions!$B$52 | G18: =IFERROR(F18/F6,0) | H18: ='Revenue Build'!F28*Assumptions!$B$52 | I18: =IFERROR(H18/H6,0) | J18: ='Revenue Build'!G28*Assumptions!$B$52 | K18: =IFERROR(J18/J6,0)
A19: Packaging & delivery supplies | B19: ='Revenue Build'!C28*Assumptions!$B$53 | C19: =IFERROR(B19/B6,0) | D19: ='Revenue Build'!D28*Assumptions!$B$53 | E19: =IFERROR(D19/D6,0) | F19: ='Revenue Build'!E28*Assumptions!$B$53 | G19: =IFERROR(F19/F6,0) | H19: ='Revenue Build'!F28*Assumptions!$B$53 | I19: =IFERROR(H19/H6,0) | J19: ='Revenue Build'!G28*Assumptions!$B$53 | K19: =IFERROR(J19/J6,0)
A20: Insurance & licenses | B20: =Assumptions!$B$54 | C20: =IFERROR(B20/B6,0) | D20: =Assumptions!$B$54 | E20: =IFERROR(D20/D6,0) | F20: =Assumptions!$B$54 | G20: =IFERROR(F20/F6,0) | H20: =Assumptions!$B$54 | I20: =IFERROR(H20/H6,0) | J20: =Assumptions!$B$54 | K20: =IFERROR(J20/J6,0)
A21: POS / SaaS | B21: =Assumptions!$B$55*12 | C21: =IFERROR(B21/B6,0) | D21: =Assumptions!$B$55*12 | E21: =IFERROR(D21/D6,0) | F21: =Assumptions!$B$55*12 | G21: =IFERROR(F21/F6,0) | H21: =Assumptions!$B$55*12 | I21: =IFERROR(H21/H6,0) | J21: =Assumptions!$B$55*12 | K21: =IFERROR(J21/J6,0)
A22: Accounting | B22: =Assumptions!$B$56*12 | C22: =IFERROR(B22/B6,0) | D22: =Assumptions!$B$56*12 | E22: =IFERROR(D22/D6,0) | F22: =Assumptions!$B$56*12 | G22: =IFERROR(F22/F6,0) | H22: =Assumptions!$B$56*12 | I22: =IFERROR(H22/H6,0) | J22: =Assumptions!$B$56*12 | K22: =IFERROR(J22/J6,0)
A23: Misc | B23: ='Revenue Build'!C28*Assumptions!$B$57 | C23: =IFERROR(B23/B6,0) | D23: ='Revenue Build'!D28*Assumptions!$B$57 | E23: =IFERROR(D23/D6,0) | F23: ='Revenue Build'!E28*Assumptions!$B$57 | G23: =IFERROR(F23/F6,0) | H23: ='Revenue Build'!F28*Assumptions!$B$57 | I23: =IFERROR(H23/H6,0) | J23: ='Revenue Build'!G28*Assumptions!$B$57 | K23: =IFERROR(J23/J6,0)
A24: Total OPEX | B24: =B14+B15+B16+B17+B18+B19+B20+B21+B22+B23 | C24: =IFERROR(B24/B6,0) | D24: =D14+D15+D16+D17+D18+D19+D20+D21+D22+D23 | E24: =IFERROR(D24/D6,0) | F24: =F14+F15+F16+F17+F18+F19+F20+F21+F22+F23 | G24: =IFERROR(F24/F6,0) | H24: =H14+H15+H16+H17+H18+H19+H20+H21+H22+H23 | I24: =IFERROR(H24/H6,0) | J24: =J14+J15+J16+J17+J18+J19+J20+J21+J22+J23 | K24: =IFERROR(J24/J6,0)
A26: TOTAL OPERATING COSTS (COGS + OPEX) | B26: =B11+B24 | C26: =IFERROR(B26/B6,0) | D26: =D11+D24 | E26: =IFERROR(D26/D6,0) | F26: =F11+F24 | G26: =IFERROR(F26/F6,0) | H26: =H11+H24 | I26: =IFERROR(H26/H6,0) | J26: =J11+J24 | K26: =IFERROR(J26/J6,0)

Sheet P&L
A1: SALVATORE PIZZA — PROFIT & LOSS
A3: Bulgaria CIT 10%. D&A = Opening CAPEX / 7 years straight-line.
A4: P&L Line | B4: % margin | C4: Y1 2026 | D4: Y2 2027 | E4: Y3 2028 | F4: Y4 2029 | G4: Y5 2030
A5: Revenue | C5: ='Revenue Build'!C28 | D5: ='Revenue Build'!D28 | E5: ='Revenue Build'!E28 | F5: ='Revenue Build'!F28 | G5: ='Revenue Build'!G28
A6: (–) COGS | C6: =-'Cost Forecast'!B11 | D6: =-'Cost Forecast'!D11 | E6: =-'Cost Forecast'!F11 | F6: =-'Cost Forecast'!H11 | G6: =-'Cost Forecast'!J11
A7: Gross Profit | C7: =C5+C6 | D7: =D5+D6 | E7: =E5+E6 | F7: =F5+F6 | G7: =G5+G6
A8: (–) Operating Expenses | C8: =-'Cost Forecast'!B24 | D8: =-'Cost Forecast'!D24 | E8: =-'Cost Forecast'!F24 | F8: =-'Cost Forecast'!H24 | G8: =-'Cost Forecast'!J24
A9: EBITDA | C9: =C7+C8 | D9: =D7+D8 | E9: =E7+E8 | F9: =F7+F8 | G9: =G7+G8
A10: (–) D&A | C10: =-Assumptions!$B$70/Assumptions!$B$72 | D10: =-Assumptions!$B$70/Assumptions!$B$72 | E10: =-Assumptions!$B$70/Assumptions!$B$72 | F10: =-Assumptions!$B$70/Assumptions!$B$72 | G10: =-Assumptions!$B$70/Assumptions!$B$72
A11: EBIT | C11: =C9+C10 | D11: =D9+D10 | E11: =E9+E10 | F11: =F9+F10 | G11: =G9+G10
A12: (–) Interest | C12: =-Assumptions!$B$80 | D12: =-Assumptions!$B$80 | E12: =-Assumptions!$B$80 | F12: =-Assumptions!$B$80 | G12: =-Assumptions!$B$80
A13: Profit Before Tax | C13: =C11+C12 | D13: =D11+D12 | E13: =E11+E12 | F13: =F11+F12 | G13: =G11+G12
A14: (–) Corporate Tax (10%) | C14: =-MAX(0,C13)*Assumptions!$B$87 | D14: =-MAX(0,D13)*Assumptions!$B$87 | E14: =-MAX(0,E13)*Assumptions!$B$87 | F14: =-MAX(0,F13)*Assumptions!$B$87 | G14: =-MAX(0,G13)*Assumptions!$B$87
A15: Net Income | C15: =C13+C14 | D15: =D13+D14 | E15: =E13+E14 | F15: =F13+F14 | G15: =G13+G14
A18: MARGIN ANALYSIS
A19: Metric | C19: Y1 2026 | D19: Y2 2027 | E19: Y3 2028 | F19: Y4 2029 | G19: Y5 2030
A20: Gross margin | C20: =C7/C5 | D20: =D7/D5 | E20: =E7/E5 | F20: =F7/F5 | G20: =G7/G5
A21: OPEX % of revenue | C21: =-C8/C5 | D21: =-D8/D5 | E21: =-E8/E5 | F21: =-F8/F5 | G21: =-G8/G5
A22: EBITDA margin | C22: =C9/C5 | D22: =D9/D5 | E22: =E9/E5 | F22: =F9/F5 | G22: =G9/G5
A23: Net margin | C23: =C15/C5 | D23: =D15/D5 | E23: =E15/E5 | F23: =F15/F5 | G23: =G15/G5

Sheet Cash Flow
A1: SALVATORE PIZZA — CASH FLOW & INVESTMENT ANALYSIS
A3: Y0 opening CAPEX + WC; FCF = EBITDA - Tax - Maintenance CAPEX. Terminal value = Y5 EBITDA × 4.5x.
A4: Line | B4: Y0 2025 | C4: Y1 2026 | D4: Y2 2027 | E4: Y3 2028 | F4: Y4 2029 | G4: Y5 2030 | H4: Terminal
A5: (–) Opening CAPEX | B5: =-Assumptions!$B$70 | C5: 0 | D5: 0 | E5: 0 | F5: 0 | G5: 0 | H5: 0
A6: (–/+) Working capital | B6: =-Assumptions!$B$76 | C6: 0 | D6: 0 | E6: 0 | F6: 0 | G6: 0 | H6: =Assumptions!$B$76
A7: EBITDA | B7: 0 | C7: ='P&L'!C9 | D7: ='P&L'!D9 | E7: ='P&L'!E9 | F7: ='P&L'!F9 | G7: ='P&L'!G9 | H7: 0
A8: (–) Cash Tax | B8: 0 | C8: ='P&L'!C14 | D8: ='P&L'!D14 | E8: ='P&L'!E14 | F8: ='P&L'!F14 | G8: ='P&L'!G14 | H8: 0
A9: (–) Maintenance CAPEX | B9: 0 | C9: =0 | D9: =-'Revenue Build'!D28*Assumptions!$B$71 | E9: =-'Revenue Build'!E28*Assumptions!$B$71 | F9: =-'Revenue Build'!F28*Assumptions!$B$71 | G9: =-'Revenue Build'!G28*Assumptions!$B$71 | H9: 0
A10: (+) Terminal Value (Y5 EBITDA × multiple) | B10: 0 | C10: 0 | D10: 0 | E10: 0 | F10: 0 | G10: 0 | H10: ='P&L'!G9*Assumptions!$B$79
A11: Free Cash Flow | B11: =SUM(B5:B10) | C11: =SUM(C5:C10) | D11: =SUM(D5:D10) | E11: =SUM(E5:E10) | F11: =SUM(F5:F10) | G11: =SUM(G5:G10) | H11: =SUM(H5:H10)
A12: Cumulative FCF | B12: =B11 | C12: =B12+C11 | D12: =C12+D11 | E12: =D12+E11 | F12: =E12+F11 | G12: =F12+G11 | H12: =G12+H11
A15: INVESTMENT METRICS
A16: Discount rate (WACC) | C16: =Assumptions!$B$78
A17: Exit EBITDA multiple | C17: =Assumptions!$B$79
A18: Total cash deployed (Y0) | C18: =-B11
A20: Cash flow vector for IRR/NPV (Y0..Y5) | C20: =B11 | D20: =C11 | E20: =D11 | F20: =E11 | G20: =F11 | H20: =G11+H11
A22: Investment Returns
A23: Total terminal proceeds (Y5 FCF + Terminal) | C23: =H20
A24: NPV @ Discount rate (BGN) | C24: =NPV(Assumptions!$B$78,D20:H20)+C20
A25: IRR | C25: =IRR(C20:H20)
A26: MOIC (Multiple on Invested Capital) | C26: =SUM(D20:H20)/(-C20)
A27: Payback period (yrs) | C27: =IFERROR(IF(C12>=0,1,IF(D12>=0,1+(-C12)/D11,IF(E12>=0,2+(-D12)/E11,IF(F12>=0,3+(-E12)/F11,IF(G12>=0,4+(-F12)/G11,99))))),99)

Sheet Sensitivity
A1: SALVATORE PIZZA — SENSITIVITY — IRR
A3: 5×5 IRR sensitivity. ASP and covers/day flexed ±15% (cols) and ±20% (rows). Note: this is an illustrative static-driver matrix — re-run model with scenario toggle for exact IRR.
A5: Covers ↓ / ASP → | B5: -0.15 | C5: -0.075 | D5: 0 | E5: 0.075 | F5: 0.15 | I5: Central Y5 EBITDA | J5: ='P&L'!G9
A6: -0.2 | B6: =((($J$5+($J$6*((1+-0.15)*(1+-0.2)-1))*0.6)*$J$8)/$J$7)^(1/5)-1 | C6: =((($J$5+($J$6*((1+-0.075)*(1+-0.2)-1))*0.6)*$J$8)/$J$7)^(1/5)-1 | D6: =((($J$5+($J$6*((1+0)*(1+-0.2)-1))*0.6)*$J$8)/$J$7)^(1/5)-1 | E6: =((($J$5+($J$6*((1+0.075)*(1+-0.2)-1))*0.6)*$J$8)/$J$7)^(1/5)-1 | F6: =((($J$5+($J$6*((1+0.15)*(1+-0.2)-1))*0.6)*$J$8)/$J$7)^(1/5)-1 | I6: Central Y5 Revenue | J6: ='P&L'!G5
A7: -0.1 | B7: =((($J$5+($J$6*((1+-0.15)*(1+-0.1)-1))*0.6)*$J$8)/$J$7)^(1/5)-1 | C7: =((($J$5+($J$6*((1+-0.075)*(1+-0.1)-1))*0.6)*$J$8)/$J$7)^(1/5)-1 | D7: =((($J$5+($J$6*((1+0)*(1+-0.1)-1))*0.6)*$J$8)/$J$7)^(1/5)-1 | E7: =((($J$5+($J$6*((1+0.075)*(1+-0.1)-1))*0.6)*$J$8)/$J$7)^(1/5)-1 | F7: =((($J$5+($J$6*((1+0.15)*(1+-0.1)-1))*0.6)*$J$8)/$J$7)^(1/5)-1 | I7: Invested (Y0) | J7: =-'Cash Flow'!B11
A8: 0 | B8: =((($J$5+($J$6*((1+-0.15)*(1+0)-1))*0.6)*$J$8)/$J$7)^(1/5)-1 | C8: =((($J$5+($J$6*((1+-0.075)*(1+0)-1))*0.6)*$J$8)/$J$7)^(1/5)-1 | D8: =((($J$5+($J$6*((1+0)*(1+0)-1))*0.6)*$J$8)/$J$7)^(1/5)-1 | E8: =((($J$5+($J$6*((1+0.075)*(1+0)-1))*0.6)*$J$8)/$J$7)^(1/5)-1 | F8: =((($J$5+($J$6*((1+0.15)*(1+0)-1))*0.6)*$J$8)/$J$7)^(1/5)-1 | I8: Exit multiple | J8: =Assumptions!$B$79
A9: 0.1 | B9: =((($J$5+($J$6*((1+-0.15)*(1+0.1)-1))*0.6)*$J$8)/$J$7)^(1/5)-1 | C9: =((($J$5+($J$6*((1+-0.075)*(1+0.1)-1))*0.6)*$J$8)/$J$7)^(1/5)-1 | D9: =((($J$5+($J$6*((1+0)*(1+0.1)-1))*0.6)*$J$8)/$J$7)^(1/5)-1 | E9: =((($J$5+($J$6*((1+0.075)*(1+0.1)-1))*0.6)*$J$8)/$J$7)^(1/5)-1 | F9: =((($J$5+($J$6*((1+0.15)*(1+0.1)-1))*0.6)*$J$8)/$J$7)^(1/5)-1
A10: 0.2 | B10: =((($J$5+($J$6*((1+-0.15)*(1+0.2)-1))*0.6)*$J$8)/$J$7)^(1/5)-1 | C10: =((($J$5+($J$6*((1+-0.075)*(1+0.2)-1))*0.6)*$J$8)/$J$7)^(1/5)-1 | D10: =((($J$5+($J$6*((1+0)*(1+0.2)-1))*0.6)*$J$8)/$J$7)^(1/5)-1 | E10: =((($J$5+($J$6*((1+0.075)*(1+0.2)-1))*0.6)*$J$8)/$J$7)^(1/5)-1 | F10: =((($J$5+($J$6*((1+0.15)*(1+0.2)-1))*0.6)*$J$8)/$J$7)^(1/5)-1
A12: Read: % change in ASP across columns; % change in covers across rows. Cells show indicative 5-yr IRR.

Sheet KPI Dashboard
A1: SALVATORE PIZZA — KPI DASHBOARD
A3: One-page operating dashboard — links live to other sheets.
A5: KPI | B5: Y1 2026 | C5: Y2 2027 | D5: Y3 2028 | E5: Y4 2029 | F5: Y5 2030
A6: Total Revenue (BGN) | B6: ='P&L'!C5 | C6: ='P&L'!D5 | D6: ='P&L'!E5 | E6: ='P&L'!F5 | F6: ='P&L'!G5
A7: Avg revenue / dine-in cover (BGN) | B7: ='Revenue Build'!C13 | C7: ='Revenue Build'!D13 | D7: ='Revenue Build'!E13 | E7: ='Revenue Build'!F13 | F7: ='Revenue Build'!G13
A8: Food cost % of revenue | B8: ='Cost Forecast'!B8/'P&L'!C5 | C8: ='Cost Forecast'!D8/'P&L'!D5 | D8: ='Cost Forecast'!F8/'P&L'!E5 | E8: ='Cost Forecast'!H8/'P&L'!F5 | F8: ='Cost Forecast'!J8/'P&L'!G5
A9: Labour % of revenue | B9: ='Cost Forecast'!B16/'P&L'!C5 | C9: ='Cost Forecast'!D16/'P&L'!D5 | D9: ='Cost Forecast'!F16/'P&L'!E5 | E9: ='Cost Forecast'!H16/'P&L'!F5 | F9: ='Cost Forecast'!J16/'P&L'!G5
A10: EBITDA margin | B10: ='P&L'!C22 | C10: ='P&L'!D22 | D10: ='P&L'!E22 | E10: ='P&L'!F22 | F10: ='P&L'!G22
A11: Pizzas/day (implied) | B11: ='Revenue Build'!C32 | C11: ='Revenue Build'!D32 | D11: ='Revenue Build'!E32 | E11: ='Revenue Build'!F32 | F11: ='Revenue Build'!G32
A12: Oven utilisation | B12: ='Revenue Build'!C34 | C12: ='Revenue Build'!D34 | D12: ='Revenue Build'!E34 | E12: ='Revenue Build'!F34 | F12: ='Revenue Build'!G34
A13: Monthly break-even revenue (BGN) | B13: =('Cost Forecast'!B24/12)/(1-('Cost Forecast'!B11/'P&L'!C5)) | C13: =('Cost Forecast'!D24/12)/(1-('Cost Forecast'!D11/'P&L'!D5)) | D13: =('Cost Forecast'!F24/12)/(1-('Cost Forecast'!F11/'P&L'!E5)) | E13: =('Cost Forecast'!H24/12)/(1-('Cost Forecast'!H11/'P&L'!F5)) | F13: =('Cost Forecast'!J24/12)/(1-('Cost Forecast'!J11/'P&L'!G5))
